Workbook

Sheet Resumen
A1: Plataforma de Eventos Online · Backlog y Roadmap v1.0
A2: Reto Técnico Líder Técnico · Scrum con sprints de 2 semanas · primera versión en 6 meses
A4: Parámetros y totales
A5: Fecha de inicio del proyecto (lunes) | C5: 46300 | D5: Supuesto: inicio el lunes 5-oct-2026. Cambiarla recalcula todas las fechas de sprints, hitos y roadmap.
A6: Duración del sprint (días calendario) | C6: 14 | D6: Requisito del reto: sprints de 2 semanas.
A7: Número de sprints | C7: =COUNT(Sprints!A5:A17) -> 13 | D7: S0 (inception) a S12 (go-live) = 26 semanas.
A8: Fin del último sprint (go-live v1.0) | C8: =MAX(Sprints!D5:D17) -> 46479
A9: Capacidad total planificada (SP) | C9: =SUM(Sprints!F5:F17) -> 460
A10: SP planificados para la v1.0 | C10: =SUMIFS(Backlog!$G$5:$G$200,Backlog!$H$5:$H$200,">=0") -> 419
A11: Utilización global | C11: =IF(C9=0,"",C10/C9) -> 0.91086957 | D11: Objetivo: 85–95 % para absorber imprevistos.
A12: Ítems del backlog | C12: =COUNTA(Backlog!$A$5:$A$200) -> 101
A13: SP estimados post v1.0 (fuera del plan) | C13: =SUMIFS(Backlog!$G$5:$G$200,Backlog!$H$5:$H$200,"Post v1.0") -> 55
A15: Supuestos
A16: • Velocidad de referencia: 5 desarrolladores × ~8 SP por sprint ≈ 40 SP. Se reduce en S0 (arranque), S5–S6 (feriados de fin de año) y S11–S12 (estabilización y go-live).
A17: • Los SP estiman el trabajo del equipo de desarrollo y QA. Las tareas de UX/UI, los documentos y las tareas de las áreas de soporte figuran sin SP (no consumen esa velocidad), pero tienen responsable y sprint.
A18: • Las cifras de capacidad son supuestos iniciales: se recalibran con la velocidad real a partir del Sprint 2.
A19: • Las columnas Inicio/Fin del Roadmap usan MINIFS y MAXIFS (Excel 2019, Microsoft 365, LibreOffice 5.2+ o Google Sheets).
A21: Equipo
A22: Rol | C22: Personas | D22: Aporta SP / responsabilidad
A23: Product Owner | C23: 1 | D23: No · Visión, priorización, aceptación, UAT
A24: Scrum Master | C24: 1 | D24: No · Facilitación, impedimentos, dependencias con áreas de soporte
A25: Líder Técnico | C25: 1 | D25: Parcial · Arquitectura, estándares, revisiones, riesgos técnicos (~30 % hands-on)
A26: Backend | C26: 2 | D26: Sí · Microservicios .NET, mensajería, persistencia
A27: Frontend | C27: 2 | D27: Sí · Web cliente, backoffice, PWA de staff
A28: FullStack | C28: 1 | D28: Sí · Funcionalidades de punta a punta, CI/CD, IaC de servicios, integraciones
A29: QA | C29: 2 | D29: Sí · Automatización, regresión, carga, soporte en UAT
A30: UX | C30: 1 | D30: No · Investigación, journeys, prototipos
A31: UI | C31: 1 | D31: No · Design system, diseño visual
A32: Total | C32: =SUM(C23:C31) -> 12 | D32: Áreas de soporte: Arquitectura, Base de Datos, Seguridad, Plataforma
A34: Leyenda
A35: Texto azul | D35: Valores editables que alimentan cálculos (fecha de inicio, SP, sprint, capacidad)
A36: Relleno amarillo | D36: Parámetros clave del plan
A37: Texto negro | D37: Fórmulas: no editar
A39: Hojas
A40: Backlog | D40: Épicas, historias, tareas técnicas, spikes, documentos y tareas de las áreas de soporte, con SP, sprint y responsable
A41: Sprints | D41: Calendario, objetivo, capacidad, carga planificada e hitos por sprint
A42: Roadmap | D42: Gantt por épica, fases, hitos y carga vs. capacidad
A43: RACI | D43: Responsabilidades del equipo y de las áreas de soporte
A44: Documentos | D44: Documentación técnica y funcional: responsable, aprobador y momento
A45: Riesgos | D45: Registro de riesgos con severidad y mitigación

Sheet Backlog
A1: Backlog de producto · v1.0
A2: Tipos: Historia · Técnica · Spike · UX/UI · Documento · Soporte (tarea de un área de soporte de TI). Filtrar con los encabezados.
A4: ID | B4: Épica | C4: Nombre de la épica | D4: Ítem | E4: Tipo | F4: Prioridad | G4: SP | H4: Sprint | I4: Responsable | J4: Área de soporte | K4: Criterio de aceptación / entregable | L4: Estado
A5: BL-001 | B5: EP01 | C5: Inception y gobierno | D5: Visión del producto, objetivos y KPI | E5: Documento | F5: Must | H5: 0 | I5: PO | J5: — | K5: Visión y KPI aprobados por el sponsor | L5: Pendiente
A6: BL-002 | B6: EP01 | C6: Inception y gobierno | D6: Story mapping y plan de releases (MoSCoW) | E6: Documento | F6: Must | H6: 0 | I6: PO · LT · SM | J6: — | K6: Mapa de historias priorizado y releases definidos | L6: Pendiente
A7: BL-003 | B7: EP01 | C7: Inception y gobierno | D7: Investigación UX: entrevistas a clientes, promotores y staff; journeys | E7: UX/UI | F7: Must | H7: 0 | I7: UX | J7: — | K7: Journeys y hallazgos compartidos con el equipo | L7: Pendiente
A8: BL-004 | B8: EP01 | C8: Inception y gobierno | D8: Documento de arquitectura (SAD, C4) y ADR iniciales | E8: Documento | F8: Must | H8: 0 | I8: LT | J8: Arquitectura | K8: SAD aprobado por el área de Arquitectura (hito H1) | L8: Pendiente
A9: BL-005 | B9: EP01 | C9: Inception y gobierno | D9: Modelo de amenazas inicial (STRIDE) y requisitos de seguridad | E9: Documento | F9: Must | H9: 0 | I9: LT | J9: Seguridad | K9: Amenazas priorizadas con controles, validado por Seguridad | L9: Pendiente
A10: BL-006 | B10: EP01 | C10: Inception y gobierno | D10: Spike: estrategia anti-sobreventa bajo carga (UPDATE condicional vs. sharding) | E10: Spike | F10: Must | G10: 3 | H10: 0 | I10: Backend | J10: BD | K10: Informe con resultados de carga y recomendación (ADR-007) | L10: Pendiente
A11: BL-007 | B11: EP01 | C11: Inception y gobierno | D11: Spike: evaluación de PSP (sandbox, webhooks, reembolsos, certificación) | E11: Spike | F11: Must | G11: 2 | H11: 0 | I11: FullStack | J11: Seguridad | K11: PSP recomendado con tiempos de certificación | L11: Pendiente
A12: BL-008 | B12: EP02 | C12: Plataforma, CI/CD y observabilidad | D12: Landing zone: cuentas AWS por entorno, VPC y conectividad | E12: Soporte | F12: Must | H12: 0 | I12: Plataforma | J12: Plataforma · Seguridad | K12: Cuentas DEV/QA/STG/PROD operativas con accesos del equipo | L12: Pendiente
A13: BL-009 | B13: EP02 | C13: Plataforma, CI/CD y observabilidad | D13: Plantilla de microservicio .NET (arquitectura limpia, outbox, OpenTelemetry, health checks) | E13: Técnica | F13: Must | G13: 5 | H13: 0 | I13: LT · Backend | J13: — | K13: Plantilla en repositorio con pruebas y README | L13: Pendiente
A14: BL-010 | B14: EP02 | C14: Plataforma, CI/CD y observabilidad | D14: Plantilla frontend (React + TypeScript + Tailwind, lint y pruebas) | E14: Técnica | F14: Must | G14: 3 | H14: 0 | I14: Frontend | J14: — | K14: Proyecto base con CI en verde | L14: Pendiente
A15: BL-011 | B15: EP02 | C15: Plataforma, CI/CD y observabilidad | D15: Pipeline CI base (build, pruebas, Sonar, SCA, secret scanning) | E15: Técnica | F15: Must | G15: 5 | H15: 0 | I15: FullStack | J15: Seguridad | K15: El pipeline bloquea PR con quality gate fallido | L15: Pendiente
A16: BL-012 | B16: EP01 | C16: Inception y gobierno | D16: Modelo de datos conceptual y lineamientos de base de datos | E16: Documento | F16: Must | H16: 1 | I16: LT | J16: BD | K16: Modelo revisado por el área de BD | L16: Pendiente
A17: BL-013 | B17: EP01 | C17: Inception y gobierno | D17: Design system (tokens, componentes, guía visual) | E17: UX/UI | F17: Must | H17: 1 | I17: UI | J17: — | K17: Design system publicado | L17: Pendiente
A18: BL-014 | B18: EP01 | C18: Inception y gobierno | D18: Prototipos de alta fidelidad: backoffice de eventos | E18: UX/UI | F18: Must | H18: 1 | I18: UX · UI | J18: — | K18: Prototipo validado por el PO | L18: Pendiente
A19: BL-015 | B19: EP02 | C19: Plataforma, CI/CD y observabilidad | D19: Módulos Terraform base (VPC, ECS, Aurora, SNS/SQS, ECR) | E19: Soporte | F19: Must | H19: 1 | I19: Plataforma | J19: Plataforma · Seguridad | K19: Módulos versionados y aprobados | L19: Pendiente
A20: BL-016 | B20: EP02 | C20: Plataforma, CI/CD y observabilidad | D20: Reglas de firewall, security groups y WAF base | E20: Soporte | F20: Must | H20: 1 | I20: Seguridad | J20: Seguridad · Plataforma | K20: Políticas aplicadas en DEV y QA | L20: Pendiente
A21: BL-017 | B21: EP02 | C21: Plataforma, CI/CD y observabilidad | D21: Terraform de servicios (task definitions, colas, tablas) sobre módulos base | E21: Técnica | F21: Must | G21: 5 | H21: 1 | I21: FullStack | J21: Plataforma | K21: Recursos de servicio creados por pipeline | L21: Pendiente
A22: BL-018 | B22: EP02 | C22: Plataforma, CI/CD y observabilidad | D22: CD a DEV y QA (build once, deploy many) | E22: Técnica | F22: Must | G22: 5 | H22: 1 | I22: FullStack | J22: Plataforma | K22: Un merge a main despliega en DEV y promueve a QA | L22: Pendiente
A23: BL-019 | B23: EP02 | C23: Plataforma, CI/CD y observabilidad | D23: Walking skeleton: event-service → SNS/SQS → notification-service con outbox e inbox | E23: Técnica | F23: Must | G23: 8 | H23: 1 | I23: Backend | J23: — | K23: Flujo asíncrono funcionando en QA (hito H2) | L23: Pendiente
A24: BL-020 | B24: EP02 | C24: Plataforma, CI/CD y observabilidad | D24: Observabilidad base: OpenTelemetry, logs JSON, dashboards y alarmas iniciales | E24: Técnica | F24: Must | G24: 3 | H24: 1 | I24: Backend | J24: Plataforma | K24: Traza de punta a punta visible | L24: Pendiente
A25: BL-021 | B25: EP04 | C25: Gestión de eventos | D25: Shell del backoffice (layout, ruteo, manejo de errores, cliente HTTP) | E25: Técnica | F25: Must | G25: 5 | H25: 1 | I25: Frontend | J25: — | K25: Shell desplegado en QA | L25: Pendiente
A26: BL-022 | B26: EP02 | C26: Plataforma, CI/CD y observabilidad | D26: Componentes base del design system en React | E26: Técnica | F26: Must | G26: 3 | H26: 1 | I26: Frontend | J26: — | K26: Componentes documentados | L26: Pendiente
A27: BL-023 | B27: EP13 | C27: Calidad, seguridad y rendimiento | D27: Estrategia y plan de pruebas; framework de automatización de API | E27: Técnica | F27: Must | G27: 5 | H27: 1 | I27: QA | J27: — | K27: Plan aprobado y primera suite en el pipeline | L27: Pendiente
A28: BL-024 | B28: EP01 | C28: Inception y gobierno | D28: Prototipos de alta fidelidad: sitio público y checkout | E28: UX/UI | F28: Must | H28: 2 | I28: UX · UI | J28: — | K28: Prototipo validado con usuarios | L28: Pendiente
A29: BL-025 | B29: EP03 | C29: Identidad y accesos | D29: Configurar Cognito: user pools, grupos (Cliente, Promotor, Admin, Staff) y app clients | E29: Técnica | F29: Must | G29: 5 | H29: 2 | I29: Backend | J29: Seguridad | K29: Login OIDC funcionando en DEV y QA | L29: Pendiente
A30: BL-026 | B30: EP03 | C30: Identidad y accesos | D30: Registro e inicio de sesión del cliente (Authorization Code + PKCE) | E30: Historia | F30: Must | G30: 5 | H30: 2 | I30: Frontend | J30: — | K30: El cliente se registra, verifica su email e inicia sesión | L30: Pendiente
A31: BL-027 | B31: EP03 | C31: Identidad y accesos | D31: Inicio de sesión del backoffice y menú por rol | E31: Historia | F31: Must | G31: 3 | H31: 2 | I31: Frontend | J31: — | K31: Cada rol ve solo sus opciones | L31: Pendiente
A32: BL-028 | B32: EP03 | C32: Identidad y accesos | D32: Autorización por rol y por recurso (anti-IDOR) en las APIs | E32: Técnica | F32: Must | G32: 5 | H32: 2 | I32: Backend | J32: Seguridad | K32: Pruebas de acceso cruzado devuelven 403/404 | L32: Pendiente
A33: BL-029 | B33: EP03 | C33: Identidad y accesos | D33: user-service: perfil, preferencias y consentimientos | E33: Historia | F33: Must | G33: 5 | H33: 2 | I33: Backend | J33: BD | K33: El cliente gestiona su perfil y consentimientos | L33: Pendiente
A34: BL-030 | B34: EP03 | C34: Identidad y accesos | D34: Alta de promotores y aprobación por el administrador | E34: Historia | F34: Must | G34: 8 | H34: 2 | I34: FullStack | J34: — | K34: Un promotor aprobado puede crear eventos | L34: Pendiente
A35: BL-031 | B35: EP03 | C35: Identidad y accesos | D35: Client Credentials entre servicios (scopes) | E35: Técnica | F35: Should | G35: 3 | H35: 2 | I35: Backend | J35: Seguridad | K35: Llamadas internas con token de servicio | L35: Pendiente
A36: BL-032 | B36: EP13 | C36: Calidad, seguridad y rendimiento | D36: Pruebas automatizadas de autenticación y autorización | E36: Técnica | F36: Must | G36: 3 | H36: 2 | I36: QA | J36: — | K36: Suite de roles e IDOR en la regresión | L36: Pendiente
A37: BL-033 | B37: EP04 | C37: Gestión de eventos | D37: Crear y editar evento en borrador con zonas, precios y aforos (API) | E37: Historia | F37: Must | G37: 8 | H37: 3 | I37: Backend | J37: BD | K37: Evento y zonas persistidos con validaciones | L37: Pendiente
A38: BL-034 | B38: EP04 | C38: Gestión de eventos | D38: Backoffice: formulario de evento y zonas | E38: Historia | F38: Must | G38: 8 | H38: 3 | I38: Frontend | J38: — | K38: El promotor crea y edita eventos con validación | L38: Pendiente
A39: BL-035 | B39: EP04 | C39: Gestión de eventos | D39: Listado de eventos del promotor (solo propios) con filtros | E39: Historia | F39: Must | G39: 3 | H39: 3 | I39: Frontend | J39: — | K39: El promotor no ve eventos de otros | L39: Pendiente
A40: BL-036 | B40: EP04 | C40: Gestión de eventos | D40: Reglas de venta: fechas de preventa y venta, límite por usuario | E40: Historia | F40: Must | G40: 5 | H40: 3 | I40: Backend | J40: — | K40: Reglas validadas en la API | L40: Pendiente
... A58: BL-054 | B58: EP07 | C58: Órdenes y checkout | D58: UI de checkout con campos alojados del PSP | E58: Historia | F58: Must | G58: 8 | H58: 6 | I58: Frontend | J58: — | K58: El cliente paga en sandbox | L58: Pendiente
...

Sheet Sprints
A1: Plan de sprints
A2: Las fechas se calculan a partir de la fecha de inicio (hoja Resumen). La capacidad (azul) es editable.
A4: Sprint | B4: Fase | C4: Inicio | D4: Fin | E4: Objetivo del sprint | F4: Capacidad (SP) | G4: SP planificados | H4: Utilización | I4: Hito | J4: Notas
A5: 0 | B5: F0 · Inception y fundaciones | C5: =Resumen!$C$5+Resumen!$C$6*A5 -> 46300 | D5: =C5+Resumen!$C$6-3 -> 46311 | E5: Inception: visión, story map, arquitectura aprobada, cuentas AWS, plantillas y CI base | F5: 20 | G5: =SUMIFS(Backlog!$G$5:$G$200,Backlog!$H$5:$H$200,A5) -> 18 | H5: =IF(F5=0,"",G5/F5) -> 0.9 | I5: H1 · Arquitectura aprobada | J5: Arranque: capacidad reducida
A6: 1 | B6: F0 · Inception y fundaciones | C6: =Resumen!$C$5+Resumen!$C$6*A6 -> 46314 | D6: =C6+Resumen!$C$6-3 -> 46325 | E6: Walking skeleton event-service → bus → notification-service en DEV/QA con IaC, observabilidad y design system | F6: 36 | G6: =SUMIFS(Backlog!$G$5:$G$200,Backlog!$H$5:$H$200,A6) -> 34 | H6: =IF(F6=0,"",G6/F6) -> 0.94444444 | I6: H2 · Walking skeleton en QA
A7: 2 | B7: F1 · Identidad, catálogo y búsqueda | C7: =Resumen!$C$5+Resumen!$C$6*A7 -> 46328 | D7: =C7+Resumen!$C$6-3 -> 46339 | E7: Identidad y accesos: Cognito, roles, login de cliente y backoffice, perfiles y promotores | F7: 40 | G7: =SUMIFS(Backlog!$G$5:$G$200,Backlog!$H$5:$H$200,A7) -> 37 | H7: =IF(F7=0,"",G7/F7) -> 0.925
A8: 3 | B8: F1 · Identidad, catálogo y búsqueda | C8: =Resumen!$C$5+Resumen!$C$6*A8 -> 46342 | D8: =C8+Resumen!$C$6-3 -> 46353 | E8: Gestión de eventos: evento, zonas, precios, aforos y reglas de venta en el backoffice | F8: 40 | G8: =SUMIFS(Backlog!$G$5:$G$200,Backlog!$H$5:$H$200,A8) -> 39 | H8: =IF(F8=0,"",G8/F8) -> 0.975
A9: 4 | B9: F1 · Identidad, catálogo y búsqueda | C9: =Resumen!$C$5+Resumen!$C$6*A9 -> 46356 | D9: =C9+Resumen!$C$6-3 -> 46367 | E9: Publicación y búsqueda: eventos de integración, OpenSearch, sitio público de búsqueda y detalle | F9: 40 | G9: =SUMIFS(Backlog!$G$5:$G$200,Backlog!$H$5:$H$200,A9) -> 36 | H9: =IF(F9=0,"",G9/F9) -> 0.9 | I9: H3 · Release interno R0 (catálogo y búsqueda) en Staging
A10: 5 | B10: F2 · Compra, pagos y tickets | C10: =Resumen!$C$5+Resumen!$C$6*A10 -> 46370 | D10: =C10+Resumen!$C$6-3 -> 46381 | E10: Inventario sin sobreventa: holds atómicos, expiración, sala de espera y selección de zona | F10: 32 | G10: =SUMIFS(Backlog!$G$5:$G$200,Backlog!$H$5:$H$200,A10) -> 29 | H10: =IF(F10=0,"",G10/F10) -> 0.90625 | J10: Feriados de fin de año: capacidad reducida
A11: 6 | B11: F2 · Compra, pagos y tickets | C11: =Resumen!$C$5+Resumen!$C$6*A11 -> 46384 | D11: =C11+Resumen!$C$6-3 -> 46395 | E11: Órdenes y pagos: saga de compra, PSP en sandbox, webhooks y checkout | F11: 28 | G11: =SUMIFS(Backlog!$G$5:$G$200,Backlog!$H$5:$H$200,A11) -> 27 | H11: =IF(F11=0,"",G11/F11) -> 0.96428571 | J11: Feriados de fin de año: capacidad reducida
A12: 7 | B12: F2 · Compra, pagos y tickets | C12: =Resumen!$C$5+Resumen!$C$6*A12 -> 46398 | D12: =C12+Resumen!$C$6-3 -> 46409 | E12: Pagos y tickets: compensaciones, reembolsos, conciliación, QR firmado y Mis tickets | F12: 40 | G12: =SUMIFS(Backlog!$G$5:$G$200,Backlog!$H$5:$H$200,A12) -> 36 | H12: =IF(F12=0,"",G12/F12) -> 0.9
A13: 8 | B13: F2 · Compra, pagos y tickets | C13: =Resumen!$C$5+Resumen!$C$6*A13 -> 46412 | D13: =C13+Resumen!$C$6-3 -> 46423 | E13: Notificaciones multicanal, antifraude y compra de punta a punta automatizada | F13: 40 | G13: =SUMIFS(Backlog!$G$5:$G$200,Backlog!$H$5:$H$200,A13) -> 34 | H13: =IF(F13=0,"",G13/F13) -> 0.85 | I13: H4 · Compra de punta a punta en QA
A14: 9 | B14: F3 · Check-in, backoffice y operación | C14: =Resumen!$C$5+Resumen!$C$6*A14 -> 46426 | D14: =C14+Resumen!$C$6-3 -> 46437 | E14: Check-in online y offline, app de staff (PWA) y aforo en tiempo real | F14: 40 | G14: =SUMIFS(Backlog!$G$5:$G$200,Backlog!$H$5:$H$200,A14) -> 37 | H14: =IF(F14=0,"",G14/F14) -> 0.925
A15: 10 | B15: F3 · Check-in, backoffice y operación | C15: =Resumen!$C$5+Resumen!$C$6*A15 -> 46440 | D15: =C15+Resumen!$C$6-3 -> 46451 | E15: Backoffice de soporte, auditoría, reportes, exportación a BI, alarmas y runbooks | F15: 40 | G15: =SUMIFS(Backlog!$G$5:$G$200,Backlog!$H$5:$H$200,A15) -> 36 | H15: =IF(F15=0,"",G15/F15) -> 0.9 | I15: H5 · Feature complete (congelamiento funcional)
A16: 11 | B16: F4 · Estabilización y salida a producción | C16: =Resumen!$C$5+Resumen!$C$6*A16 -> 46454 | D16: =C16+Resumen!$C$6-3 -> 46465 | E16: Estabilización: carga de preventa, pentest, recuperación ante desastres, accesibilidad y defectos | F16: 36 | G16: =SUMIFS(Backlog!$G$5:$G$200,Backlog!$H$5:$H$200,A16) -> 34 | H16: =IF(F16=0,"",G16/F16) -> 0.94444444 | J16: Pentest externo en paralelo
A17: 12 | B17: F4 · Estabilización y salida a producción | C17: =Resumen!$C$5+Resumen!$C$6*A17 -> 46468 | D17: =C17+Resumen!$C$6-3 -> 46479 | E17: UAT, aprovisionamiento de producción, datos iniciales, manuales y go-live | F17: 28 | G17: =SUMIFS(Backlog!$G$5:$G$200,Backlog!$H$5:$H$200,A17) -> 22 | H17: =IF(F17=0,"",G17/F17) -> 0.78571429 | I17: H6 · Go-live v1.0 | J17: Hipercuidado de 2 semanas posterior al go-live
A18: Total | F18: =SUM(F5:F17) -> 460 | G18: =SUM(G5:G17) -> 419 | H18: =IF(F18=0,"",G18/F18) -> 0.91086957

Sheet Roadmap
A1: Roadmap v1.0 · Gantt por épica
A2: Las barras se calculan desde el Backlog (sprint mínimo y máximo de cada épica). Cambiar el sprint de un ítem mueve la barra.
A4: Épica | B4: Nombre | C4: Inicio | D4: Fin | E4: SP | F4: 0 | G4: 1 | H4: 2 | I4: 3 | J4: 4 | K4: 5 | L4: 6 | M4: 7 | N4: 8 | O4: 9 | P4: 10 | Q4: 11 | R4: 12
A5: Inicio del sprint | F5: =INDEX(Sprints!$C$5:$C$17,MATCH(F$4,Sprints!$A$5:$A$17,0)) -> 46300 | G5: =INDEX(Sprints!$C$5:$C$17,MATCH(G$4,Sprints!$A$5:$A$17,0)) -> 46314 | H5: =INDEX(Sprints!$C$5:$C$17,MATCH(H$4,Sprints!$A$5:$A$17,0)) -> 46328 | I5: =INDEX(Sprints!$C$5:$C$17,MATCH(I$4,Sprints!$A$5:$A$17,0)) -> 46342 | J5: =INDEX(Sprints!$C$5:$C$17,MATCH(J$4,Sprints!$A$5:$A$17,0)) -> 46356 | K5: =INDEX(Sprints!$C$5:$C$17,MATCH(K$4,Sprints!$A$5:$A$17,0)) -> 46370 | L5: =INDEX(Sprints!$C$5:$C$17,MATCH(L$4,Sprints!$A$5:$A$17,0)) -> 46384 | M5: =INDEX(Sprints!$C$5:$C$17,MATCH(M$4,Sprints!$A$5:$A$17,0)) -> 46398 | ... R5: =INDEX(Sprints!$C$5:$C$17,MATCH(R$4,Sprints!$A$5:$A$17,0)) -> 46468
A6: Fase | F6: =LEFT(INDEX(Sprints!$B$5:$B$17,MATCH(F$4,Sprints!$A$5:$A$17,0)),2) -> F0 | G6: =LEFT(INDEX(Sprints!$B$5:$B$17,MATCH(G$4,Sprints!$A$5:$A$17,0)),2) -> F0 | H6: =LEFT(INDEX(Sprints!$B$5:$B$17,MATCH(H$4,Sprints!$A$5:$A$17,0)),2) -> F1 | I6: =LEFT(INDEX(Sprints!$B$5:$B$17,MATCH(I$4,Sprints!$A$5:$A$17,0)),2) -> F1 | J6: =LEFT(INDEX(Sprints!$B$5:$B$17,MATCH(J$4,Sprints!$A$5:$A$17,0)),2) -> F1 | K6: =LEFT(INDEX(Sprints!$B$5:$B$17,MATCH(K$4,Sprints!$A$5:$A$17,0)),2) -> F2 | L6: =LEFT(INDEX(Sprints!$B$5:$B$17,MATCH(L$4,Sprints!$A$5:$A$17,0)),2) -> F2 | M6: =LEFT(INDEX(Sprints!$B$5:$B$17,MATCH(M$4,Sprints!$A$5:$A$17,0)),2) -> F2 | ... R6: =LEFT(INDEX(Sprints!$B$5:$B$17,MATCH(R$4,Sprints!$A$5:$A$17,0)),2) -> F4
A7: Hito | F7: =IF(INDEX(Sprints!$I$5:$I$17,MATCH(F$4,Sprints!$A$5:$A$17,0))="","","◆ "&LEFT(INDEX(Sprints!$I$5:$I$17,MATCH(F$4,Sprints!$A$5:$A$17,0)),2)) -> ◆ H1 | G7: =IF(INDEX(Sprints!$I$5:$I$17,MATCH(G$4,Sprints!$A$5:$A$17,0))="","","◆ "&LEFT(INDEX(Sprints!$I$5:$I$17,MATCH(G$4,Sprints!$A$5:$A$17,0)),2)) -> ◆ H2 | H7: =IF(INDEX(Sprints!$I$5:$I$17,MATCH(H$4,Sprints!$A$5:$A$17,0))="","","◆ "&LEFT(INDEX(Sprints!$I$5:$I$17,MATCH(H$4,Sprints!$A$5:$A$17,0)),2)) | I7: =IF(INDEX(Sprints!$I$5:$I$17,MATCH(I$4,Sprints!$A$5:$A$17,0))="","","◆ "&LEFT(INDEX(Sprints!$I$5:$I$17,MATCH(I$4,Sprints!$A$5:$A$17,0)),2)) | J7: =IF(INDEX(Sprints!$I$5:$I$17,MATCH(J$4,Sprints!$A$5:$A$17,0))="","","◆ "&LEFT(INDEX(Sprints!$I$5:$I$17,MATCH(J$4,Sprints!$A$5:$A$17,0)),2)) -> ◆ H3 | K7: =IF(INDEX(Sprints!$I$5:$I$17,MATCH(K$4,Sprints!$A$5:$A$17,0))="","","◆ "&LEFT(INDEX(Sprints!$I$5:$I$17,MATCH(K$4,Sprints!$A$5:$A$17,0)),2)) | L7: =IF(INDEX(Sprints!$I$5:$I$17,MATCH(L$4,Sprints!$A$5:$A$17,0))="","","◆ "&LEFT(INDEX(Sprints!$I$5:$I$17,MATCH(L$4,Sprints!$A$5:$A$17,0)),2)) | M7: =IF(INDEX(Sprints!$I$5:$I$17,MATCH(M$4,Sprints!$A$5:$A$17,0))="","","◆ "&LEFT(INDEX(Sprints!$I$5:$I$17,MATCH(M$4,Sprints!$A$5:$A$17,0)),2)) | ... R7: =IF(INDEX(Sprints!$I$5:$I$17,MATCH(R$4,Sprints!$A$5:$A$17,0))="","","◆ "&LEFT(INDEX(Sprints!$I$5:$I$17,MATCH(R$4,Sprints!$A$5:$A$17,0)),2)) -> ◆ H6
A8: EP01 | B8: Inception y gobierno | C8: =IF(COUNTIFS(Backlog!$B$5:$B$200,$A8,Backlog!$H$5:$H$200,">=0")=0,"",_xlfn.MINIFS(Backlog!$H$5:$H$200,Backlog!$B$5:$B$200,$A8)) -> 0 | D8: =IF(COUNTIFS(Backlog!$B$5:$B$200,$A8,Backlog!$H$5:$H$200,">=0")=0,"",_xlfn.MAXIFS(Backlog!$H$5:$H$200,Backlog!$B$5:$B$200,$A8)) -> 2 | E8: =SUMIFS(Backlog!$G$5:$G$200,Backlog!$B$5:$B$200,$A8,Backlog!$H$5:$H$200,">=0") -> 5
A9: EP02 | B9: Plataforma, CI/CD y observabilidad | C9: =IF(COUNTIFS(Backlog!$B$5:$B$200,$A9,Backlog!$H$5:$H$200,">=0")=0,"",_xlfn.MINIFS(Backlog!$H$5:$H$200,Backlog!$B$5:$B$200,$A9)) -> 0 | D9: =IF(COUNTIFS(Backlog!$B$5:$B$200,$A9,Backlog!$H$5:$H$200,">=0")=0,"",_xlfn.MAXIFS(Backlog!$H$5:$H$200,Backlog!$B$5:$B$200,$A9)) -> 10 | E9: =SUMIFS(Backlog!$G$5:$G$200,Backlog!$B$5:$B$200,$A9,Backlog!$H$5:$H$200,">=0") -> 40
A10: EP03 | B10: Identidad y accesos | C10: =IF(COUNTIFS(Backlog!$B$5:$B$200,$A10,Backlog!$H$5:$H$200,">=0")=0,"",_xlfn.MINIFS(Backlog!$H$5:$H$200,Backlog!$B$5:$B$200,$A10)) -> 2 | D10: =IF(COUNTIFS(Backlog!$B$5:$B$200,$A10,Backlog!$H$5:$H$200,">=0")=0,"",_xlfn.MAXIFS(Backlog!$H$5:$H$200,Backlog!$B$5:$B$200,$A10)) -> 2 | E10: =SUMIFS(Backlog!$G$5:$G$200,Backlog!$B$5:$B$200,$A10,Backlog!$H$5:$H$200,">=0") -> 34
A11: EP04 | B11: Gestión de eventos | C11: =IF(COUNTIFS(Backlog!$B$5:$B$200,$A11,Backlog!$H$5:$H$200,">=0")=0,"",_xlfn.MINIFS(Backlog!$H$5:$H$200,Backlog!$B$5:$B$200,$A11)) -> 1 | D11: =IF(COUNTIFS(Backlog!$B$5:$B$200,$A11,Backlog!$H$5:$H$200,">=0")=0,"",_xlfn.MAXIFS(Backlog!$H$5:$H$200,Backlog!$B$5:$B$200,$A11)) -> 4 | E11: =SUMIFS(Backlog!$G$5:$G$200,Backlog!$B$5:$B$200,$A11,Backlog!$H$5:$H$200,">=0") -> 44
A12: EP05 | B12: Búsqueda y catálogo público | C12: =IF(COUNTIFS(Backlog!$B$5:$B$200,$A12,Backlog!$H$5:$H$200,">=0")=0,"",_xlfn.MINIFS(Backlog!$H$5:$H$200,Backlog!$B$5:$B$200,$A12)) -> 4 | D12: =IF(COUNTIFS(Backlog!$B$5:$B$200,$A12,Backlog!$H$5:$H$200,">=0")=0,"",_xlfn.MAXIFS(Backlog!$H$5:$H$200,Backlog!$B$5:$B$200,$A12)) -> 4 | E12: =SUMIFS(Backlog!$G$5:$G$200,Backlog!$B$5:$B$200,$A12,Backlog!$H$5:$H$200,">=0") -> 26
A13: EP06 | B13: Inventario y reservas | C13: =IF(COUNTIFS(Backlog!$B$5:$B$200,$A13,Backlog!$H$5:$H$200,">=0")=0,"",_xlfn.MINIFS(Backlog!$H$5:$H$200,Backlog!$B$5:$B$200,$A13)) -> 5 | D13: =IF(COUNTIFS(Backlog!$B$5:$B$200,$A13,Backlog!$H$5:$H$200,">=0")=0,"",_xlfn.MAXIFS(Backlog!$H$5:$H$200,Backlog!$B$5:$B$200,$A13)) -> 5 | E13: =SUMIFS(Backlog!$G$5:$G$200,Backlog!$B$5:$B$200,$A13,Backlog!$H$5:$H$200,">=0") -> 26
A14: EP07 | B14: Órdenes y checkout | C14: =IF(COUNTIFS(Backlog!$B$5:$B$200,$A14,Backlog!$H$5:$H$200,">=0")=0,"",_xlfn.MINIFS(Backlog!$H$5:$H$200,Backlog!$B$5:$B$200,$A14)) -> 6 | D14: =IF(COUNTIFS(Backlog!$B$5:$B$200,$A14,Backlog!$H$5:$H$200,">=0")=0,"",_xlfn.MAXIFS(Backlog!$H$5:$H$200,Backlog!$B$5:$B$200,$A14)) -> 7 | E14: =SUMIFS(Backlog!$G$5:$G$200,Backlog!$B$5:$B$200,$A14,Backlog!$H$5:$H$200,">=0") -> 26
A15: EP08 | B15: Pagos | C15: =IF(COUNTIFS(Backlog!$B$5:$B$200,$A15,Backlog!$H$5:$H$200,">=0")=0,"",_xlfn.MINIFS(Backlog!$H$5:$H$200,Backlog!$B$5:$B$200,$A15)) -> 6 | D15: =IF(COUNTIFS(Backlog!$B$5:$B$200,$A15,Backlog!$H$5:$H$200,">=0")=0,"",_xlfn.MAXIFS(Backlog!$H$5:$H$200,Backlog!$B$5:$B$200,$A15)) -> 8 | E15: =SUMIFS(Backlog!$G$5:$G$200,Backlog!$B$5:$B$200,$A15,Backlog!$H$5:$H$200,">=0") -> 26
A16: EP09 | B16: Tickets | C16: =IF(COUNTIFS(Backlog!$B$5:$B$200,$A16,Backlog!$H$5:$H$200,">=0")=0,"",_xlfn.MINIFS(Backlog!$H$5:$H$200,Backlog!$B$5:$B$200,$A16)) -> 7 | D16: =IF(COUNTIFS(Backlog!$B$5:$B$200,$A16,Backlog!$H$5:$H$200,">=0")=0,"",_xlfn.MAXIFS(Backlog!$H$5:$H$200,Backlog!$B$5:$B$200,$A16)) -> 8 | E16: =SUMIFS(Backlog!$G$5:$G$200,Backlog!$B$5:$B$200,$A16,Backlog!$H$5:$H$200,">=0") -> 21
A17: EP10 | B17: Notificaciones | C17: =IF(COUNTIFS(Backlog!$B$5:$B$200,$A17,Backlog!$H$5:$H$200,">=0")=0,"",_xlfn.MINIFS(Backlog!$H$5:$H$200,Backlog!$B$5:$B$200,$A17)) -> 4 | D17: =IF(COUNTIFS(Backlog!$B$5:$B$200,$A17,Backlog!$H$5:$H$200,">=0")=0,"",_xlfn.MAXIFS(Backlog!$H$5:$H$200,Backlog!$B$5:$B$200,$A17)) -> 8 | E17: =SUMIFS(Backlog!$G$5:$G$200,Backlog!$B$5:$B$200,$A17,Backlog!$H$5:$H$200,">=0") -> 21
A18: EP11 | B18: Check-in | C18: =IF(COUNTIFS(Backlog!$B$5:$B$200,$A18,Backlog!$H$5:$H$200,">=0")=0,"",_xlfn.MINIFS(Backlog!$H$5:$H$200,Backlog!$B$5:$B$200,$A18)) -> 9 | D18: =IF(COUNTIFS(Backlog!$B$5:$B$200,$A18,Backlog!$H$5:$H$200,">=0")=0,"",_xlfn.MAXIFS(Backlog!$H$5:$H$200,Backlog!$B$5:$B$200,$A18)) -> 9 | E18: =SUMIFS(Backlog!$G$5:$G$200,Backlog!$B$5:$B$200,$A18,Backlog!$H$5:$H$200,">=0") -> 34
A19: EP12 | B19: Backoffice, auditoría y BI | C19: =IF(COUNTIFS(Backlog!$B$5:$B$200,$A19,Backlog!$H$5:$H$200,">=0")=0,"",_xlfn.MINIFS(Backlog!$H$5:$H$200,Backlog!$B$5:$B$200,$A19)) -> 10 | D19: =IF(COUNTIFS(Backlog!$B$5:$B$200,$A19,Backlog!$H$5:$H$200,">=0")=0,"",_xlfn.MAXIFS(Backlog!$H$5:$H$200,Backlog!$B$5:$B$200,$A19)) -> 10 | E19: =SUMIFS(Backlog!$G$5:$G$200,Backlog!$B$5:$B$200,$A19,Backlog!$H$5:$H$200,">=0") -> 33
... A21: EP14 | B21: Salida a producción | C21: =IF(COUNTIFS(Backlog!$B$5:$B$200,$A21,Backlog!$H$5:$H$200,">=0")=0,"",_xlfn.MINIFS(Backlog!$H$5:$H$200,Backlog!$B$5:$B$200,$A21)) -> 12 | D21: =IF(COUNTIFS(Backlog!$B$5:$B$200,$A21,Backlog!$H$5:$H$200,">=0")=0,"",_xlfn.MAXIFS(Backlog!$H$5:$H$200,Backlog!$B$5:$B$200,$A21)) -> 12 | E21: =SUMIFS(Backlog!$G$5:$G$200,Backlog!$B$5:$B$200,$A21,Backlog!$H$5:$H$200,">=0") -> 22
A23: SP planificados | F23: =SUMIFS(Backlog!$G$5:$G$200,Backlog!$H$5:$H$200,F$4) -> 18 | G23: =SUMIFS(Backlog!$G$5:$G$200,Backlog!$H$5:$H$200,G$4) -> 34 | H23: =SUMIFS(Backlog!$G$5:$G$200,Backlog!$H$5:$H$200,H$4) -> 37 | I23: =SUMIFS(Backlog!$G$5:$G$200,Backlog!$H$5:$H$200,I$4) -> 39 | J23: =SUMIFS(Backlog!$G$5:$G$200,Backlog!$H$5:$H$200,J$4) -> 36 | K23: =SUMIFS(Backlog!$G$5:$G$200,Backlog!$H$5:$H$200,K$4) -> 29 | L23: =SUMIFS(Backlog!$G$5:$G$200,Backlog!$H$5:$H$200,L$4) -> 27 | M23: =SUMIFS(Backlog!$G$5:$G$200,Backlog!$H$5:$H$200,M$4) -> 36 | ... R23: =SUMIFS(Backlog!$G$5:$G$200,Backlog!$H$5:$H$200,R$4) -> 22
A24: Capacidad (SP) | F24: =INDEX(Sprints!$F$5:$F$17,MATCH(F$4,Sprints!$A$5:$A$17,0)) -> 20 | G24: =INDEX(Sprints!$F$5:$F$17,MATCH(G$4,Sprints!$A$5:$A$17,0)) -> 36 | H24: =INDEX(Sprints!$F$5:$F$17,MATCH(H$4,Sprints!$A$5:$A$17,0)) -> 40 | I24: =INDEX(Sprints!$F$5:$F$17,MATCH(I$4,Sprints!$A$5:$A$17,0)) -> 40 | J24: =INDEX(Sprints!$F$5:$F$17,MATCH(J$4,Sprints!$A$5:$A$17,0)) -> 40 | K24: =INDEX(Sprints!$F$5:$F$17,MATCH(K$4,Sprints!$A$5:$A$17,0)) -> 32 | L24: =INDEX(Sprints!$F$5:$F$17,MATCH(L$4,Sprints!$A$5:$A$17,0)) -> 28 | M24: =INDEX(Sprints!$F$5:$F$17,MATCH(M$4,Sprints!$A$5:$A$17,0)) -> 40 | ... R24: =INDEX(Sprints!$F$5:$F$17,MATCH(R$4,Sprints!$A$5:$A$17,0)) -> 28
A25: Utilización | F25: =IF(F24=0,"",F23/F24) -> 0.9 | G25: =IF(G24=0,"",G23/G24) -> 0.94444444 | H25: =IF(H24=0,"",H23/H24) -> 0.925 | I25: =IF(I24=0,"",I23/I24) -> 0.975 | J25: =IF(J24=0,"",J23/J24) -> 0.9 | K25: =IF(K24=0,"",K23/K24) -> 0.90625 | L25: =IF(L24=0,"",L23/L24) -> 0.96428571 | M25: =IF(M24=0,"",M23/M24) -> 0.9 | ... R25: =IF(R24=0,"",R23/R24) -> 0.78571429
A27: Hitos
A28: Sprint | B28: Hito | E28: Fecha
A29: =Sprints!A5 -> 0 | B29: =Sprints!I5 -> H1 · Arquitectura aprobada | E29: =Sprints!D5 -> 46311
A30: =Sprints!A6 -> 1 | B30: =Sprints!I6 -> H2 · Walking skeleton en QA | E30: =Sprints!D6 -> 46325
A31: =Sprints!A9 -> 4 | B31: =Sprints!I9 -> H3 · Release interno R0 (catálogo y búsqueda) en Staging | E31: =Sprints!D9 -> 46367
A32: =Sprints!A13 -> 8 | B32: =Sprints!I13 -> H4 · Compra de punta a punta en QA | E32: =Sprints!D13 -> 46423
A33: =Sprints!A15 -> 10 | B33: =Sprints!I15 -> H5 · Feature complete (congelamiento funcional) | E33: =Sprints!D15 -> 46451
A34: =Sprints!A17 -> 12 | B34: =Sprints!I17 -> H6 · Go-live v1.0 | E34: =Sprints!D17 -> 46479

Sheet RACI
A1: Matriz RACI
A2: R = Responsable · A = Aprueba · C = Consultado · I = Informado
A4: Actividad | B4: PO | C4: SM | D4: LT | E4: Dev (BE/FE/FS) | F4: QA | G4: UX/UI | H4: Arquitectura | I4: BD | J4: Seguridad | K4: Plataforma
A5: Visión y priorización del backlog | B5: A/R | C5: C | D5: C | E5: I | F5: I | G5: C | H5: I | I5: I | J5: I | K5: I
A6: Diseño de arquitectura (SAD, ADR) | B6: I | C6: I | D6: R | E6: C | F6: I | G6: I | H6: A | I6: C | J6: C | K6: C
A7: Modelo de datos y scripts | B7: I | C7: I | D7: A | E7: R | F7: I | G7: I | H7: C | I7: C | J7: I | K7: I
A8: Ejecución de scripts en Staging y Producción | B8: I | C8: I | D8: C | E8: C | F8: I | G8: I | H8: I | I8: A/R | J8: I | K8: C
A9: Aprovisionamiento de nube / on-premise (IaC) | B9: I | C9: I | D9: C | E9: C | F9: I | G9: I | H9: C | I9: C | J9: C | K9: A/R
A10: Firewall, WAF, IAM y políticas de seguridad | B10: I | C10: I | D10: C | E10: C | F10: I | G10: I | H10: I | I10: I | J10: A | K10: R
A11: Modelo de amenazas y revisiones de seguridad | B11: I | C11: I | D11: R | E11: C | F11: C | G11: I | H11: C | I11: I | J11: A | K11: I
A12: Pipelines de CI/CD | B12: I | C12: I | D12: A | E12: R | F12: C | G12: I | H12: I | I12: I | J12: C | K12: C
A13: Desarrollo y pruebas unitarias | B13: I | C13: I | D13: A | E13: R | F13: C | G13: C | H13: I | I13: I | J13: I | K13: I
A14: Revisión de código | B14: I | C14: I | D14: A | E14: R | F14: I | G14: I | H14: I | I14: I | J14: I | K14: I
A15: Diseño UX/UI | B15: A | C15: I | D15: C | E15: C | F15: C | G15: R | H15: I | I15: I | J15: I | K15: I
... A24: Hipercuidado post go-live | B24: I | C24: C | D24: A | E24: R | F24: C | G24: I | H24: I | I24: C | J24: C | K24: R

Sheet Documentos
A1: Documentación técnica y funcional
A2: Documentos que exige el proceso DEV → QA → Staging → Producción
A4: # | B4: Documento | C4: Tipo | D4: Responsable | E4: Aprueba | F4: Cuándo
A5: 1 | B5: Visión del producto, objetivos y KPI | C5: Funcional | D5: PO | E5: Sponsor | F5: Sprint 0
A6: 2 | B6: Mapa de historias y roadmap | C6: Funcional | D6: PO + LT + SM | E6: Sponsor | F6: Sprint 0 (vivo)
A7: 3 | B7: Historias de usuario con criterios Gherkin | C7: Funcional | D7: PO | E7: PO | F7: Continuo (DoR)
A8: 4 | B8: Reglas de negocio (venta, aforos, reembolsos, check-in) | C8: Funcional | D8: PO | E8: Negocio | F8: Sprints 1–7
A9: 5 | B9: Prototipos UX y design system | C9: Funcional | D9: UX / UI | E9: PO | F9: Sprints 0–2 y por épica
A10: 6 | B10: Documento de arquitectura (SAD, C4) + ADR | C10: Técnico | D10: LT | E10: Arquitectura | F10: Sprint 0 (vivo)
A11: 7 | B11: Modelo de amenazas y requisitos de seguridad | C11: Técnico | D11: LT + Seguridad | E11: Seguridad | F11: Sprint 0; se actualiza por épica
A12: 8 | B12: Modelo de datos y diccionario de datos por servicio | C12: Técnico | D12: Dev + LT | E12: BD | F12: Por servicio
A13: 9 | B13: Contratos de API (OpenAPI) y catálogo de eventos (AsyncAPI) | C13: Técnico | D13: Dev | E13: LT | F13: Por historia
A14: 10 | B14: Diseño de infraestructura y módulos Terraform | C14: Técnico | D14: Plataforma + FS | E14: Arquitectura + Seguridad | F14: Sprints 0–1
A15: 11 | B15: Estrategia y plan de pruebas, informes por sprint | C15: Técnico | D15: QA | E15: LT + PO | F15: Sprint 1; por sprint
A16: 12 | B16: Plan e informe de pruebas de carga | C16: Técnico | D16: QA + BE | E16: LT | F16: Sprint 11
... A24: 20 | B24: README y guía de contribución por repositorio | C24: Técnico | D24: Dev | E24: LT | F24: Sprint 0 (vivo)

Sheet Riesgos
A1: Registro de riesgos
A2: Probabilidad e impacto: 1 = bajo, 2 = medio, 3 = alto (editables). Severidad = P × I; Alto ≥ 6, Medio ≥ 3.
A4: ID | B4: Riesgo | C4: Probabilidad | D4: Impacto | E4: Severidad | F4: Nivel | G4: Mitigación | H4: Responsable | I4: Revisión
A5: R01 | B5: Retrasos en aprobaciones y aprovisionamiento de las áreas de soporte | C5: 3 | D5: 3 | E5: =C5*D5 -> 9 | F5: =IF(E5>=6,"Alto",IF(E5>=3,"Medio","Bajo")) -> Alto | G5: Solicitudes con un sprint de anticipación, historias habilitadoras, sincronización semanal, módulos Terraform de autoservicio | H5: SM · LT | I5: Cada sprint
A6: R02 | B6: Integración o certificación del PSP más lenta de lo previsto | C6: 2 | D6: 3 | E6: =C6*D6 -> 6 | F6: =IF(E6>=6,"Alto",IF(E6>=3,"Medio","Bajo")) -> Alto | G6: Spike en S0, sandbox temprano, contacto técnico con el PSP, PSP alternativo identificado | H6: LT · FullStack | I6: S0, S6
A7: R03 | B7: Volúmenes de preventa superiores a lo estimado | C7: 2 | D7: 3 | E7: =C7*D7 -> 6 | F7: =IF(E7>=6,"Alto",IF(E7>=3,"Medio","Bajo")) -> Alto | G7: Sala de espera, pruebas de carga desde S5, autoescalado, contadores particionados | H7: LT · QA | I7: S5, S11
A8: R04 | B8: Alcance mayor a la capacidad disponible en 6 meses | C8: 3 | D8: 2 | E8: =C8*D8 -> 6 | F8: =IF(E8>=6,"Alto",IF(E8>=3,"Medio","Bajo")) -> Alto | G8: Priorización MoSCoW, recortes predefinidos (Wallet, SMS/WhatsApp, BI), burn-up quincenal con el PO | H8: PO · SM | I8: Cada sprint
A9: R05 | B9: Menor capacidad en diciembre y enero (vacaciones y feriados) | C9: 3 | D9: 2 | E9: =C9*D9 -> 6 | F9: =IF(E9>=6,"Alto",IF(E9>=3,"Medio","Bajo")) -> Alto | G9: Capacidad reducida en S5–S6, plan de vacaciones escalonado | H9: SM | I9: S4
A10: R06 | B10: Curva de aprendizaje en arquitectura orientada a eventos y AWS | C10: 2 | D10: 2 | E10: =C10*D10 -> 4 | F10: =IF(E10>=6,"Alto",IF(E10>=3,"Medio","Bajo")) -> Medio | G10: Plantilla de servicio, pairing, guías y revisión de código del LT | H10: LT | I10: S0–S3
A11: R07 | B11: Hallazgos críticos de seguridad cerca del go-live | C11: 2 | D11: 3 | E11: =C11*D11 -> 6 | F11: =IF(E11>=6,"Alto",IF(E11>=3,"Medio","Bajo")) -> Alto | G11: SAST/DAST continuos, revisiones de seguridad por épica, pentest en S11 con tiempo de remediación | H11: LT · Seguridad | I11: S11
A12: R08 | B12: Fallas de conectividad en recintos durante el check-in | C12: 2 | D12: 2 | E12: =C12*D12 -> 4 | F12: =IF(E12>=6,"Alto",IF(E12>=3,"Medio","Bajo")) -> Medio | G12: Modo offline con manifiesto firmado y pruebas de campo en S9 | H12: LT | I12: S9
A13: R09 | B13: Incumplimiento de protección de datos personales o PCI | C13: 1 | D13: 3 | E13: =C13*D13 -> 3 | F13: =IF(E13>=6,"Alto",IF(E13>=3,"Medio","Bajo")) -> Medio | G13: Campos alojados del PSP, minimización de PII, revisión legal y de Seguridad | H13: PO · Seguridad | I13: S2, S6
A14: R10 | B14: El LT se convierte en cuello de botella de decisiones y revisiones | C14: 2 | D14: 2 | E14: =C14*D14 -> 4 | F14: =IF(E14>=6,"Alto",IF(E14>=3,"Medio","Bajo")) -> Medio | G14: Delegar revisiones en seniors, ADR y guías de estándares | H14: LT · SM | I14: Cada sprint
A15: R11 | B15: Cambios de licencia en librerías de terceros | C15: 1 | D15: 2 | E15: =C15*D15 -> 2 | F15: =IF(E15>=6,"Alto",IF(E15>=3,"Medio","Bajo")) -> Bajo | G15: Versiones con licencia abierta fijadas y revisión de dependencias en el pipeline | H15: LT | I15: S0
